<?xml version="1.0" encoding="utf-8"?>
<!-- This URDF was automatically created by SolidWorks to URDF Exporter! Originally created by Stephen Brawner (brawner@gmail.com) 
     Commit Version: 1.6.0-4-g7f85cfe  Build Version: 1.6.7995.38578
     For more information, please see http://wiki.ros.org/sw_urdf_exporter -->
<robot
  name="Aloha">
  <link
    name="base_link">
    <inertial>
      <origin
        xyz="-0.00084647910851246 0.00978916757496985 0.344753325406094"
        rpy="0 0 0" />
      <mass
        value="5.09802085015176" />
      <inertia
        ixx="0.0213914677302785"
        ixy="-9.32121685832386E-05"
        ixz="2.18297110088875E-05"
        iyy="0.020094368938593"
        iyz="-0.000213141208765021"
        izz="0.0220967466492654" />
    </inertial>
    <visual>
      <origin
        xyz="0 0 0"
        rpy="0 0 0" />
      <geometry>
        <mesh
          filename="package://alohamini_description/meshes/base_link.STL" />
      </geometry>
      <material
        name="">
        <color
          rgba="1 1 1 1" />
      </material>
    </visual>
    <collision>
      <origin
        xyz="0 0 0"
        rpy="0 0 0" />
      <geometry>
        <mesh
          filename="package://alohamini_description/meshes/base_link.STL" />
      </geometry>
    </collision>
  </link>
  <link
    name="wheel1">
    <inertial>
      <origin
        xyz="-5.2748796340582E-05 0.0157741139634841 -1.84430449176598E-07"
        rpy="0 0 0" />
      <mass
        value="0.19481896281763" />
      <inertia
        ixx="5.08892096796909E-05"
        ixy="3.60517539503935E-11"
        ixz="2.69071538213238E-11"
        iyy="9.36352341038526E-05"
        iyz="-4.45292183145822E-12"
        izz="5.08902241573002E-05" />
    </inertial>
    <visual>
      <origin
        xyz="0 0 0"
        rpy="0 0 0" />
      <geometry>
        <mesh
          filename="package://alohamini_description/meshes/wheel1.STL" />
      </geometry>
      <material
        name="">
        <color
          rgba="1 1 1 1" />
      </material>
    </visual>
    <collision>
      <origin
        xyz="0 0 0"
        rpy="0 0 0" />
      <geometry>
        <mesh
          filename="package://alohamini_description/meshes/wheel1.STL" />
      </geometry>
    </collision>
  </link>
  <joint
    name="wheel1"
    type="continuous">
    <origin
      xyz="-0.1538 0.091161 0.0422"
      rpy="0 0 -2.1099" />
    <parent
      link="base_link" />
    <child
      link="wheel1" />
    <axis
      xyz="0 -1 0" />
  </joint>
  <link
    name="wheel2">
    <inertial>
      <origin
        xyz="-6.44947300230958E-06 0.0157740656100239 -5.23561600380557E-05"
        rpy="0 0 0" />
      <mass
        value="0.194818035649416" />
      <inertia
        ixx="5.08900024988905E-05"
        ixy="-1.20873751512226E-12"
        ixz="-2.02779746634605E-10"
        iyy="9.36349961033418E-05"
        iyz="5.35464291484247E-11"
        izz="5.08890471060775E-05" />
    </inertial>
    <visual>
      <origin
        xyz="0 0 0"
        rpy="0 0 0" />
      <geometry>
        <mesh
          filename="package://alohamini_description/meshes/wheel2.STL" />
      </geometry>
      <material
        name="">
        <color
          rgba="1 1 1 1" />
      </material>
    </visual>
    <collision>
      <origin
        xyz="0 0 0"
        rpy="0 0 0" />
      <geometry>
        <mesh
          filename="package://alohamini_description/meshes/wheel2.STL" />
      </geometry>
    </collision>
  </link>
  <joint
    name="wheel2"
    type="continuous">
    <origin
      xyz="0.15563 0.087993 0.0422"
      rpy="0 0 2.086" />
    <parent
      link="base_link" />
    <child
      link="wheel2" />
    <axis
      xyz="0 -1 0" />
  </joint>
  <link
    name="wheel3">
    <inertial>
      <origin
        xyz="0.000217589099159171 0.0157726511952609 -4.56400979924609E-05"
        rpy="0 0 0" />
      <mass
        value="0.194818526867466" />
      <inertia
        ixx="5.08999061873463E-05"
        ixy="6.61616290797392E-07"
        ixz="-7.54847308347756E-10"
        iyy="9.36248071320913E-05"
        iyz="7.68531292230303E-11"
        izz="5.08898375022648E-05" />
    </inertial>
    <visual>
      <origin
        xyz="0 0 0"
        rpy="0 0 0" />
      <geometry>
        <mesh
          filename="package://alohamini_description/meshes/wheel3.STL" />
      </geometry>
      <material
        name="">
        <color
          rgba="1 1 1 1" />
      </material>
    </visual>
    <collision>
      <origin
        xyz="0 0 0"
        rpy="0 0 0" />
      <geometry>
        <mesh
          filename="package://alohamini_description/meshes/wheel3.STL" />
      </geometry>
    </collision>
  </link>
  <joint
    name="wheel3"
    type="continuous">
    <origin
      xyz="-0.0020354 -0.17875 0.0422"
      rpy="0 0 0" />
    <parent
      link="base_link" />
    <child
      link="wheel3" />
    <axis
      xyz="-0.015476 -0.99988 0" />
  </joint>
  <link
    name="vertical_link">
    <inertial>
      <origin
        xyz="-0.000281866140488002 0.00785823838067955 0.630167237552405"
        rpy="0 0 0" />
      <mass
        value="1.13349901272872" />
      <inertia
        ixx="0.0010858428483705"
        ixy="2.13306252507509E-05"
        ixz="-1.00486949790508E-05"
        iyy="0.00311024638919642"
        iyz="-2.96414805022489E-05"
        izz="0.0024076600321941" />
    </inertial>
    <visual>
      <origin
        xyz="0 0 0"
        rpy="0 0 0" />
      <geometry>
        <mesh
          filename="package://alohamini_description/meshes/vertical_link.STL" />
      </geometry>
      <material
        name="">
        <color
          rgba="1 1 1 1" />
      </material>
    </visual>
    <collision>
      <origin
        xyz="0 0 0"
        rpy="0 0 0" />
      <geometry>
        <mesh
          filename="package://alohamini_description/meshes/vertical_link.STL" />
      </geometry>
    </collision>
  </link>
  <joint
    name="vertical_move"
    type="prismatic">
    <origin
      xyz="-0.001045 -0.067891 0.064"
      rpy="0 0 0" />
    <parent
      link="base_link" />
    <child
      link="vertical_link" />
    <axis
      xyz="0 1.8801E-05 1" />
    <limit
      lower="0"
      upper="0"
      effort="0"
      velocity="0" />
  </joint>
  <link
    name="left_base">
    <inertial>
      <origin
        xyz="-6.47167646904735E-05 0.0317790321031433 0.0165976346519832"
        rpy="0 0 0" />
      <mass
        value="0.198100409133884" />
      <inertia
        ixx="0.000137416766071961"
        ixy="-1.82517377942839E-09"
        ixz="-5.13449093551759E-07"
        iyy="0.000177539441067423"
        iyz="2.132896783062E-05"
        izz="0.0001503685199807" />
    </inertial>
    <visual>
      <origin
        xyz="0 0 0"
        rpy="0 0 0" />
      <geometry>
        <mesh
          filename="package://alohamini_description/meshes/left_base.STL" />
      </geometry>
      <material
        name="">
        <color
          rgba="0.964705882352941 0.964705882352941 0.952941176470588 1" />
      </material>
    </visual>
    <collision>
      <origin
        xyz="0 0 0"
        rpy="0 0 0" />
      <geometry>
        <mesh
          filename="package://alohamini_description/meshes/left_base.STL" />
      </geometry>
    </collision>
  </link>
  <joint
    name="left_base"
    type="fixed">
    <origin
      xyz="0.15726 0.026474 0.68821"
      rpy="1.5721 0 -0.01193" />
    <parent
      link="vertical_link" />
    <child
      link="left_base" />
    <axis
      xyz="0 0 0" />
  </joint>
  <link
    name="left_link1">
    <inertial>
      <origin
        xyz="0.000121106970690763 -0.0313187111675913 0.0119674003207884"
        rpy="0 0 0" />
      <mass
        value="0.124705001245189" />
      <inertia
        ixx="5.98529439039593E-05"
        ixy="4.23009347760015E-08"
        ixz="4.23863604085012E-07"
        iyy="5.56041421022497E-05"
        iyz="4.7788290550065E-06"
        izz="3.02532949332968E-05" />
    </inertial>
    <visual>
      <origin
        xyz="0 0 0"
        rpy="0 0 0" />
      <geometry>
        <mesh
          filename="package://alohamini_description/meshes/left_link1.STL" />
      </geometry>
      <material
        name="">
        <color
          rgba="0.964705882352941 0.964705882352941 0.952941176470588 1" />
      </material>
    </visual>
    <collision>
      <origin
        xyz="0 0 0"
        rpy="0 0 0" />
      <geometry>
        <mesh
          filename="package://alohamini_description/meshes/left_link1.STL" />
      </geometry>
    </collision>
  </link>
  <joint
    name="left_joint1"
    type="revolute">
    <origin
      xyz="-9.9427E-05 0.065387 0.045495"
      rpy="-1.5721 0.01193 -1.5058E-05" />
    <parent
      link="left_base" />
    <child
      link="left_link1" />
    <axis
      xyz="0.00011908 0.0099879 -0.99995" />
    <limit
      lower="0"
      upper="0"
      effort="0"
      velocity="0" />
  </joint>
  <link
    name="left_link2">
    <inertial>
      <origin
        xyz="0.019956873522225 0.0742856296056551 0.00422113879640418"
        rpy="0 0 0" />
      <mass
        value="0.159995189384934" />
      <inertia
        ixx="0.000151783987720491"
        ixy="1.09262655684205E-06"
        ixz="1.21662497181061E-07"
        iyy="5.76463942492128E-05"
        iyz="7.49535020674174E-07"
        izz="0.000186896896161095" />
    </inertial>
    <visual>
      <origin
        xyz="0 0 0"
        rpy="0 0 0" />
      <geometry>
        <mesh
          filename="package://alohamini_description/meshes/left_link2.STL" />
      </geometry>
      <material
        name="">
        <color
          rgba="0.964705882352941 0.964705882352941 0.952941176470588 1" />
      </material>
    </visual>
    <collision>
      <origin
        xyz="0 0 0"
        rpy="0 0 0" />
      <geometry>
        <mesh
          filename="package://alohamini_description/meshes/left_link2.STL" />
      </geometry>
    </collision>
  </link>
  <joint
    name="left_joint2"
    type="revolute">
    <origin
      xyz="-0.0172799395963306 -0.0311811002780606 0.0539361523404946"
      rpy="0 0 0" />
    <parent
      link="left_link1" />
    <child
      link="left_link2" />
    <axis
      xyz="0.999994864047587 -0.00320379392081127 8.70801950002401E-05" />
    <limit
      lower="0"
      upper="0"
      effort="0"
      velocity="0" />
  </joint>
  <link
    name="left_link3">
    <inertial>
      <origin
        xyz="0.0188635530589078 -0.0764818324673495 0.000740365189654368"
        rpy="0 0 0" />
      <mass
        value="0.135542971850972" />
      <inertia
        ixx="9.79530639893018E-05"
        ixy="7.32525825400078E-07"
        ixz="-1.97978431727559E-07"
        iyy="3.97033329850519E-05"
        iyz="-2.49654893442067E-06"
        izz="0.000125313695411449" />
    </inertial>
    <visual>
      <origin
        xyz="0 0 0"
        rpy="0 0 0" />
      <geometry>
        <mesh
          filename="package://alohamini_description/meshes/left_link3.STL" />
      </geometry>
      <material
        name="">
        <color
          rgba="0.964705882352941 0.964705882352941 0.952941176470588 1" />
      </material>
    </visual>
    <collision>
      <origin
        xyz="0 0 0"
        rpy="0 0 0" />
      <geometry>
        <mesh
          filename="package://alohamini_description/meshes/left_link3.STL" />
      </geometry>
    </collision>
  </link>
  <joint
    name="left_joint3"
    type="revolute">
    <origin
      xyz="0.0028523 0.11238 0.028829"
      rpy="0 0 0" />
    <parent
      link="left_link2" />
    <child
      link="left_link3" />
    <axis
      xyz="0.99996 -0.0032908 0.0088132" />
    <limit
      lower="0"
      upper="0"
      effort="0"
      velocity="0" />
  </joint>
  <link
    name="left_link4">
    <inertial>
      <origin
        xyz="0.0279838202754113 -0.0363068236889853 0.000384829033235112"
        rpy="0 0 0" />
      <mass
        value="0.0742878691881685" />
      <inertia
        ixx="1.66990659139949E-05"
        ixy="1.97720472060619E-06"
        ixz="-2.54232662541019E-07"
        iyy="2.43741118311199E-05"
        iyz="6.90575207676445E-08"
        izz="3.14317929408492E-05" />
    </inertial>
    <visual>
      <origin
        xyz="0 0 0"
        rpy="0 0 0" />
      <geometry>
        <mesh
          filename="package://alohamini_description/meshes/left_link4.STL" />
      </geometry>
      <material
        name="">
        <color
          rgba="0.964705882352941 0.964705882352941 0.952941176470588 1" />
      </material>
    </visual>
    <collision>
      <origin
        xyz="0 0 0"
        rpy="0 0 0" />
      <geometry>
        <mesh
          filename="package://alohamini_description/meshes/left_link4.STL" />
      </geometry>
    </collision>
  </link>
  <joint
    name="left_joint4"
    type="revolute">
    <origin
      xyz="0.00048209729405399 -0.134148581563103 0.00362381075655138"
      rpy="0 0 0" />
    <parent
      link="left_link3" />
    <child
      link="left_link4" />
    <axis
      xyz="0.999774464019127 -0.0121028846500289 0.0174511110940406" />
    <limit
      lower="0"
      upper="0"
      effort="0"
      velocity="0" />
  </joint>
  <link
    name="left_link5">
    <inertial>
      <origin
        xyz="8.08393796061513E-05 -0.0263409418103688 -0.00560236977442241"
        rpy="0 0 0" />
      <mass
        value="0.0992047568868334" />
      <inertia
        ixx="4.92449125031436E-05"
        ixy="-2.53381198127316E-07"
        ixz="-4.26839506651897E-07"
        iyy="2.71532027390863E-05"
        iyz="-6.95500472386489E-06"
        izz="3.91386942187985E-05" />
    </inertial>
    <visual>
      <origin
        xyz="0 0 0"
        rpy="0 0 0" />
      <geometry>
        <mesh
          filename="package://alohamini_description/meshes/left_link5.STL" />
      </geometry>
      <material
        name="">
        <color
          rgba="0.964705882352941 0.964705882352941 0.952941176470588 1" />
      </material>
    </visual>
    <collision>
      <origin
        xyz="0 0 0"
        rpy="0 0 0" />
      <geometry>
        <mesh
          filename="package://alohamini_description/meshes/left_link5.STL" />
      </geometry>
    </collision>
  </link>
  <joint
    name="left_joint5"
    type="revolute">
    <origin
      xyz="0.0197383915384675 -0.0617903364033804 -0.000262136225517406"
      rpy="0 0 0" />
    <parent
      link="left_link4" />
    <child
      link="left_link5" />
    <axis
      xyz="0.0119284594940202 0.999878198776736 0.0100647635386641" />
    <limit
      lower="0"
      upper="0"
      effort="0"
      velocity="0" />
  </joint>
  <link
    name="left_link6">
    <inertial>
      <origin
        xyz="-0.0204038927902523 -0.00159758044103914 0.029746450173969"
        rpy="0 0 0" />
      <mass
        value="0.0208454114831758" />
      <inertia
        ixx="9.14110734632438E-06"
        ixy="3.37607572091266E-08"
        ixz="-1.30023681677212E-07"
        iyy="1.1431117316603E-05"
        iyz="6.42781435293997E-07"
        izz="3.29303532243366E-06" />
    </inertial>
    <visual>
      <origin
        xyz="0 0 0"
        rpy="0 0 0" />
      <geometry>
        <mesh
          filename="package://alohamini_description/meshes/left_link6.STL" />
      </geometry>
      <material
        name="">
        <color
          rgba="0.964705882352941 0.964705882352941 0.952941176470588 1" />
      </material>
    </visual>
    <collision>
      <origin
        xyz="0 0 0"
        rpy="0 0 0" />
      <geometry>
        <mesh
          filename="package://alohamini_description/meshes/left_link6.STL" />
      </geometry>
    </collision>
  </link>
  <joint
    name="left_joint6"
    type="revolute">
    <origin
      xyz="0.0187720220742788 -0.0238281541937461 0.0200035092438084"
      rpy="0 0 0" />
    <parent
      link="left_link5" />
    <child
      link="left_link6" />
    <axis
      xyz="-0.999889727846743 0.0120164296808642 -0.00872568417324989" />
    <limit
      lower="0"
      upper="0"
      effort="0"
      velocity="0" />
  </joint>
  <link
    name="right_base">
    <inertial>
      <origin
        xyz="-6.47167852975139E-05 0.0317790320234692 0.0165976345779274"
        rpy="0 0 0" />
      <mass
        value="0.198100409607737" />
      <inertia
        ixx="0.000137416766189558"
        ixy="-1.82525111822434E-09"
        ixz="-5.1344915804598E-07"
        iyy="0.000177539441510464"
        iyz="2.13289677353662E-05"
        izz="0.000150368519811328" />
    </inertial>
    <visual>
      <origin
        xyz="0 0 0"
        rpy="0 0 0" />
      <geometry>
        <mesh
          filename="package://alohamini_description/meshes/right_base.STL" />
      </geometry>
      <material
        name="">
        <color
          rgba="0.964705882352941 0.964705882352941 0.952941176470588 1" />
      </material>
    </visual>
    <collision>
      <origin
        xyz="0 0 0"
        rpy="0 0 0" />
      <geometry>
        <mesh
          filename="package://alohamini_description/meshes/right_base.STL" />
      </geometry>
    </collision>
  </link>
  <joint
    name="right_base"
    type="fixed">
    <origin
      xyz="-0.156575640990368 0.0302182544430658 0.688907726663402"
      rpy="1.5720584644847 0 -0.0119300103453133" />
    <parent
      link="vertical_link" />
    <child
      link="right_base" />
    <axis
      xyz="0 0 0" />
  </joint>
  <link
    name="right_link1">
    <inertial>
      <origin
        xyz="0.000121106969499962 -0.0313187111595207 0.011967400309894"
        rpy="0 0 0" />
      <mass
        value="0.124705001332934" />
      <inertia
        ixx="5.98529439281542E-05"
        ixy="4.23009393057866E-08"
        ixz="4.23863587037058E-07"
        iyy="5.56041421363056E-05"
        iyz="4.77882907361453E-06"
        izz="3.02532949711444E-05" />
    </inertial>
    <visual>
      <origin
        xyz="0 0 0"
        rpy="0 0 0" />
      <geometry>
        <mesh
          filename="package://alohamini_description/meshes/right_link1.STL" />
      </geometry>
      <material
        name="">
        <color
          rgba="0.964705882352941 0.964705882352941 0.952941176470588 1" />
      </material>
    </visual>
    <collision>
      <origin
        xyz="0 0 0"
        rpy="0 0 0" />
      <geometry>
        <mesh
          filename="package://alohamini_description/meshes/right_link1.STL" />
      </geometry>
    </collision>
  </link>
  <joint
    name="right_joint1"
    type="revolute">
    <origin
      xyz="-9.94268621290484E-05 0.0653870978342812 0.04549462735273"
      rpy="-1.5720585543069 0.0119300008426609 -1.50580260816763E-05" />
    <parent
      link="right_base" />
    <child
      link="right_link1" />
    <axis
      xyz="0.000119075661457425 0.00998790806073686 -0.999950112512398" />
    <limit
      lower="0"
      upper="0"
      effort="0"
      velocity="0" />
  </joint>
  <link
    name="right_link2">
    <inertial>
      <origin
        xyz="0.0199568735153524 0.0742856296207353 0.00422113879547792"
        rpy="0 0 0" />
      <mass
        value="0.159995189339826" />
      <inertia
        ixx="0.000151783987647815"
        ixy="1.09262650936436E-06"
        ixz="1.21662505806737E-07"
        iyy="5.76463942183647E-05"
        iyz="7.49535009312794E-07"
        izz="0.000186896896059229" />
    </inertial>
    <visual>
      <origin
        xyz="0 0 0"
        rpy="0 0 0" />
      <geometry>
        <mesh
          filename="package://alohamini_description/meshes/right_link2.STL" />
      </geometry>
      <material
        name="">
        <color
          rgba="0.964705882352941 0.964705882352941 0.952941176470588 1" />
      </material>
    </visual>
    <collision>
      <origin
        xyz="0 0 0"
        rpy="0 0 0" />
      <geometry>
        <mesh
          filename="package://alohamini_description/meshes/right_link2.STL" />
      </geometry>
    </collision>
  </link>
  <joint
    name="right_joint2"
    type="revolute">
    <origin
      xyz="-0.0172799395963307 -0.0311811002780605 0.0539361523404946"
      rpy="0 0 0" />
    <parent
      link="right_link1" />
    <child
      link="right_link2" />
    <axis
      xyz="0.999994864047587 -0.00320379392081127 8.70801950002401E-05" />
    <limit
      lower="0"
      upper="0"
      effort="0"
      velocity="0" />
  </joint>
  <link
    name="right_link3">
    <inertial>
      <origin
        xyz="0.0188635531409881 -0.0764818322790424 0.000740365178020785"
        rpy="0 0 0" />
      <mass
        value="0.135542972322652" />
      <inertia
        ixx="9.79530645616033E-05"
        ixy="7.32525422088505E-07"
        ixz="-1.97978409310946E-07"
        iyy="3.97033332707025E-05"
        iyz="-2.49654890226816E-06"
        izz="0.00012531369626649" />
    </inertial>
    <visual>
      <origin
        xyz="0 0 0"
        rpy="0 0 0" />
      <geometry>
        <mesh
          filename="package://alohamini_description/meshes/right_link3.STL" />
      </geometry>
      <material
        name="">
        <color
          rgba="0.964705882352941 0.964705882352941 0.952941176470588 1" />
      </material>
    </visual>
    <collision>
      <origin
        xyz="0 0 0"
        rpy="0 0 0" />
      <geometry>
        <mesh
          filename="package://alohamini_description/meshes/right_link3.STL" />
      </geometry>
    </collision>
  </link>
  <joint
    name="right_joint3"
    type="revolute">
    <origin
      xyz="0.00285228244048635 0.112379078107107 0.0288286304493108"
      rpy="0 0 0" />
    <parent
      link="right_link2" />
    <child
      link="right_link3" />
    <axis
      xyz="0.999955748189333 -0.00329083176439995 0.0088131770326472" />
    <limit
      lower="0"
      upper="0"
      effort="0"
      velocity="0" />
  </joint>
  <link
    name="right_link4">
    <inertial>
      <origin
        xyz="0.0279838202822244 -0.0363068237772076 0.00038482906176196"
        rpy="0 0 0" />
      <mass
        value="0.0742878695973153" />
      <inertia
        ixx="1.66990661768294E-05"
        ixy="1.97720479323567E-06"
        ixz="-2.54232674368644E-07"
        iyy="2.43741118850697E-05"
        iyz="6.90575778720147E-08"
        izz="3.14317932103669E-05" />
    </inertial>
    <visual>
      <origin
        xyz="0 0 0"
        rpy="0 0 0" />
      <geometry>
        <mesh
          filename="package://alohamini_description/meshes/right_link4.STL" />
      </geometry>
      <material
        name="">
        <color
          rgba="0.964705882352941 0.964705882352941 0.952941176470588 1" />
      </material>
    </visual>
    <collision>
      <origin
        xyz="0 0 0"
        rpy="0 0 0" />
      <geometry>
        <mesh
          filename="package://alohamini_description/meshes/right_link4.STL" />
      </geometry>
    </collision>
  </link>
  <joint
    name="right_joint4"
    type="revolute">
    <origin
      xyz="0.000482097294054018 -0.134148581563103 0.00362381075655149"
      rpy="0 0 0" />
    <parent
      link="right_link3" />
    <child
      link="right_link4" />
    <axis
      xyz="0.999774464019126 -0.0121028846500287 0.0174511110940404" />
    <limit
      lower="0"
      upper="0"
      effort="0"
      velocity="0" />
  </joint>
  <link
    name="right_link5">
    <inertial>
      <origin
        xyz="8.08398808658795E-05 -0.0263409414128249 -0.0056023692609708"
        rpy="0 0 0" />
      <mass
        value="0.0992047534563596" />
      <inertia
        ixx="4.9244911952362E-05"
        ixy="-2.53380764715712E-07"
        ixz="-4.26839214341626E-07"
        iyy="2.71532017310361E-05"
        iyz="-6.95500454208295E-06"
        izz="3.9138693130784E-05" />
    </inertial>
    <visual>
      <origin
        xyz="0 0 0"
        rpy="0 0 0" />
      <geometry>
        <mesh
          filename="package://alohamini_description/meshes/right_link5.STL" />
      </geometry>
      <material
        name="">
        <color
          rgba="0.964705882352941 0.964705882352941 0.952941176470588 1" />
      </material>
    </visual>
    <collision>
      <origin
        xyz="0 0 0"
        rpy="0 0 0" />
      <geometry>
        <mesh
          filename="package://alohamini_description/meshes/right_link5.STL" />
      </geometry>
    </collision>
  </link>
  <joint
    name="right_joint5"
    type="revolute">
    <origin
      xyz="0.0197383915384675 -0.0617903364033804 -0.000262136225517295"
      rpy="0 0 0" />
    <parent
      link="right_link4" />
    <child
      link="right_link5" />
    <axis
      xyz="0.0119284594940119 0.999878198776736 0.0100647635386643" />
    <limit
      lower="0"
      upper="0"
      effort="0"
      velocity="0" />
  </joint>
  <link
    name="right_link6">
    <inertial>
      <origin
        xyz="-0.0204038927575424 -0.00159758043417435 0.0297464502009193"
        rpy="0 0 0" />
      <mass
        value="0.0208454115141475" />
      <inertia
        ixx="9.14110734343226E-06"
        ixy="3.37607612259518E-08"
        ixz="-1.30023709907373E-07"
        iyy="1.14311173177543E-05"
        iyz="6.42781426848458E-07"
        izz="3.29303532232764E-06" />
    </inertial>
    <visual>
      <origin
        xyz="0 0 0"
        rpy="0 0 0" />
      <geometry>
        <mesh
          filename="package://alohamini_description/meshes/right_link6.STL" />
      </geometry>
      <material
        name="">
        <color
          rgba="0.964705882352941 0.964705882352941 0.952941176470588 1" />
      </material>
    </visual>
    <collision>
      <origin
        xyz="0 0 0"
        rpy="0 0 0" />
      <geometry>
        <mesh
          filename="package://alohamini_description/meshes/right_link6.STL" />
      </geometry>
    </collision>
  </link>
  <joint
    name="right_joint6"
    type="revolute">
    <origin
      xyz="0.0187720220742787 -0.023828154193746 0.0200035092438087"
      rpy="0 0 0" />
    <parent
      link="right_link5" />
    <child
      link="right_link6" />
    <axis
      xyz="-0.999889727846743 0.0120164296808642 -0.00872568417324984" />
    <limit
      lower="0"
      upper="0"
      effort="0"
      velocity="0" />
  </joint>
  <!-- Navigation sensor frames added for micro-ROS lidar/IMU topics.
       TODO: replace origin xyz/rpy with measured sensor poses relative to base_link.
       The frame names must match /scan.header.frame_id and /imu.header.frame_id. -->
  <link name="laser_frame" />
  <joint name="base_link_to_laser_frame" type="fixed">
    <origin xyz="0 0 0" rpy="0 0 0" />
    <parent link="base_link" />
    <child link="laser_frame" />
  </joint>

  <link name="imu_frame" />
  <joint name="base_link_to_imu_frame" type="fixed">
    <origin xyz="0 0 0" rpy="0 0 0" />
    <parent link="base_link" />
    <child link="imu_frame" />
  </joint>
</robot>